Workbook

Sheet Dashboard
B2: XBOX GAME PASS · VENDAS DE ASSINATURAS
B3: 295 assinaturas de 2024. Escolha os filtros nas células amarelas; indicadores e gráficos se atualizam.
B5: Plano | F5: Tipo de assinatura | J5: Renovação automática
B6: Todos | F6: Todos | J6: Todos | N6: Para limpar, volte os três filtros para Todos.
B8: Faturamento | E8: Assinaturas | H8: Ticket médio | K8: Complementos | N8: Cupons concedidos | Q8: Renovação automática
B9: =Cálculos!C9 -> 7633 | E9: =Cálculos!C10 -> 295 | H9: =Cálculos!C11 -> 25.874576 | K9: =Cálculos!C14 -> 6820 | N9: =Cálculos!C13 -> 2122 | Q9: =Cálculos!C18 -> 0.50169492
B11: soma de Total Value | E11: vendas no recorte | H11: faturamento ÷ assinaturas | K11: =IF(Cálculos!C12=0,"",ROUND(Cálculos!C16*100,0)&"% do valor bruto") -> 70% do valor bruto | N11: =IF(Cálculos!C12=0,"",ROUND(Cálculos!C15*100,0)&"% do valor bruto") -> 22% do valor bruto | Q11: das assinaturas
B13: Qual tipo de assinatura gera mais faturamento? | K13: A renovação automática vale mais por assinatura?
B14: =IF(Cálculos!C10=0,"Sem assinaturas com esses filtros.","Assinaturas "&INDEX(Cálculos!B26:B28,MATCH(MAX(Cálculos!D26:D28),Cálculos!D26:D28,0))&" geram "&ROUND(MAX(Cálculos!D26:D28)/Cálculos!D29*100,0)&"% do faturamento ("&INDEX(Cálculos!C26:C28,MATCH(MAX(Cálculos!D26:D28),Cálculos!D26:D28,0))&" assinaturas). O maior ticket médio é do tipo "&INDEX(Cálculos!B26:B28,MATCH(MAX(Cálculos!E26:E28),Cálculos!E26:E28,0))&": "&ROUND(MAX(Cálculos!E26:E28),1)&" por assinatura.") -> Assinaturas Monthly geram 47% do faturamento (139 assinaturas). O maior ticket médio é do tipo Quarterly: 27.2 por assinatura. | K14: =IF(Cálculos!C35=0,"Sem assinaturas com esses filtros.","Com renovação automática o ticket médio é "&ROUND(Cálculos!E33,1)&", contra "&ROUND(Cálculos!E34,1)&" sem renovação. O faturamento é "&Cálculos!D33&" com renovação e "&Cálculos!D34&" sem. O cupom médio é "&ROUND(Cálculos!F33,1)&" com renovação e "&ROUND(Cálculos!F34,1)&" sem.") -> Com renovação automática o ticket médio é 25.6, contra 26.2 sem renovação. O faturamento é 3786 com renovação e 3847 sem. O cupom médio é 7.2 com renovação e 7.2 sem.
B31: Quanto os complementos somam em cada plano? | K31: Como o faturamento evolui mês a mês?
B32: =IF(Cálculos!G42=0,"Sem assinaturas com esses filtros.","EA Play e Minecraft somam "&(Cálculos!D42+Cálculos!E42)&", ou "&ROUND((Cálculos!D42+Cálculos!E42)/(Cálculos!C42+Cálculos!D42+Cálculos!E42)*100,0)&"% do valor bruto. "&IF(AND(Cálculos!D39=0,Cálculos!D40=0,Cálculos!D41>0),"O EA Play só aparece no plano Ultimate. ","")&"Os cupons tiram "&Cálculos!F42&" do valor bruto.") -> EA Play e Minecraft somam 6820, ou 70% do valor bruto. O EA Play só aparece no plano Ultimate. Os cupons tiram 2122 do valor bruto. | K32: =IF(Cálculos!E58=0,"Sem assinaturas com esses filtros.","O mês de maior faturamento é "&INDEX(Cálculos!B46:B57,MATCH(MAX(Cálculos!E46:E57),Cálculos!E46:E57,0))&" ("&MAX(Cálculos!E46:E57)&"). Janeiro e fevereiro têm poucas vendas na base, e dezembro só vai até 16/12.") -> O mês de maior faturamento é Out (832). Janeiro e fevereiro têm poucas vendas na base, e dezembro só vai até 16/12.
B50: Como ler: cada gráfico respeita os filtros acima, exceto a própria dimensão que ele detalha (o gráfico por tipo mostra todos os tipos, e assim por diante).
B51: Base: base.xlsx do desafio (295 assinaturas, 2024). A base não informa a moeda, por isso os valores aparecem sem símbolo. Total Value é o valor registrado em cada venda.
B52: Conferência: em todas as linhas, Total Value = preço da assinatura + EA Play + Minecraft − cupom (ver aba Cálculos).

Sheet Cálculos
B2: Cálculos do dashboard
B3: Tudo aqui é fórmula sobre a aba Bases. Os filtros vêm do Dashboard (células amarelas).
B4: Critério do plano | C4: =IF(Dashboard!$B$6="Todos","*",Dashboard!$B$6) -> *
B5: Critério do tipo | C5: =IF(Dashboard!$F$6="Todos","*",Dashboard!$F$6) -> *
B6: Critério da renovação | C6: =IF(Dashboard!$J$6="Todos","*",Dashboard!$J$6) -> *
B8: Indicadores gerais (respeitam os três filtros)
B9: Faturamento (Total Value) | C9: =SUMIFS(Bases!$M$2:$M$1000,Bases!$C$2:$C$1000,$C$4,Bases!$G$2:$G$1000,$C$5,Bases!$E$2:$E$1000,$C$6) -> 7633
B10: Assinaturas | C10: =COUNTIFS(Bases!$C$2:$C$1000,$C$4,Bases!$G$2:$G$1000,$C$5,Bases!$E$2:$E$1000,$C$6) -> 295
B11: Ticket médio | C11: =IF(C10=0,0,C9/C10) -> 25.874576
B12: Valor bruto (preço + complementos) | C12: =SUMIFS(Bases!$F$2:$F$1000,Bases!$C$2:$C$1000,$C$4,Bases!$G$2:$G$1000,$C$5,Bases!$E$2:$E$1000,$C$6)+SUMIFS(Bases!$O$2:$O$1000,Bases!$C$2:$C$1000,$C$4,Bases!$G$2:$G$1000,$C$5,Bases!$E$2:$E$1000,$C$6)+SUMIFS(Bases!$K$2:$K$1000,Bases!$C$2:$C$1000,$C$4,Bases!$G$2:$G$1000,$C$5,Bases!$E$2:$E$1000,$C$6) -> 9755
B13: Cupons concedidos | C13: =SUMIFS(Bases!$L$2:$L$1000,Bases!$C$2:$C$1000,$C$4,Bases!$G$2:$G$1000,$C$5,Bases!$E$2:$E$1000,$C$6) -> 2122
B14: Receita de complementos (EA Play + Minecraft) | C14: =SUMIFS(Bases!$O$2:$O$1000,Bases!$C$2:$C$1000,$C$4,Bases!$G$2:$G$1000,$C$5,Bases!$E$2:$E$1000,$C$6)+SUMIFS(Bases!$K$2:$K$1000,Bases!$C$2:$C$1000,$C$4,Bases!$G$2:$G$1000,$C$5,Bases!$E$2:$E$1000,$C$6) -> 6820
B15: Cupons como % do valor bruto | C15: =IF(C12=0,0,C13/C12) -> 0.21752947
B16: Complementos como % do valor bruto | C16: =IF(C12=0,0,C14/C12) -> 0.69912865
B17: Assinaturas com renovação automática | C17: =COUNTIFS(Bases!$C$2:$C$1000,$C$4,Bases!$G$2:$G$1000,$C$5,Bases!$E$2:$E$1000,$C$6,Bases!$E$2:$E$1000,"Yes") -> 148
B18: % com renovação automática | C18: =IF(C10=0,0,C17/C10) -> 0.50169492
B20: Linhas na base | C20: =COUNTA(Bases!$A$2:$A$1000) -> 295
B21: Linhas com Total Value divergente | C21: =COUNTIF(Bases!$Q$2:$Q$1000,"Divergente") -> 0
B22: Conferência da base | C22: =IF(C21=0,"OK: Total Value = preço + EA Play + Minecraft − cupom","Divergente") -> OK: Total Value = preço + EA Play + Minecraft − cupom
B24: Pergunta 1: faturamento por tipo de assinatura (respeita plano e renovação; mostra todos os tipos)
B25: Tipo | C25: Assinaturas | D25: Faturamento | E25: Ticket médio | F25: % do faturamento
B26: Monthly | C26: =COUNTIFS(Bases!$C$2:$C$1000,$C$4,Bases!$G$2:$G$1000,$B26,Bases!$E$2:$E$1000,$C$6) -> 139 | D26: =SUMIFS(Bases!$M$2:$M$1000,Bases!$C$2:$C$1000,$C$4,Bases!$G$2:$G$1000,$B26,Bases!$E$2:$E$1000,$C$6) -> 3571 | E26: =IF(C26=0,0,D26/C26) -> 25.690647 | F26: =IF($D$29=0,0,D26/$D$29) -> 0.46783702
B27: Quarterly | C27: =COUNTIFS(Bases!$C$2:$C$1000,$C$4,Bases!$G$2:$G$1000,$B27,Bases!$E$2:$E$1000,$C$6) -> 85 | D27: =SUMIFS(Bases!$M$2:$M$1000,Bases!$C$2:$C$1000,$C$4,Bases!$G$2:$G$1000,$B27,Bases!$E$2:$E$1000,$C$6) -> 2308 | E27: =IF(C27=0,0,D27/C27) -> 27.152941 | F27: =IF($D$29=0,0,D27/$D$29) -> 0.30237128
B28: Annual | C28: =COUNTIFS(Bases!$C$2:$C$1000,$C$4,Bases!$G$2:$G$1000,$B28,Bases!$E$2:$E$1000,$C$6) -> 71 | D28: =SUMIFS(Bases!$M$2:$M$1000,Bases!$C$2:$C$1000,$C$4,Bases!$G$2:$G$1000,$B28,Bases!$E$2:$E$1000,$C$6) -> 1754 | E28: =IF(C28=0,0,D28/C28) -> 24.704225 | F28: =IF($D$29=0,0,D28/$D$29) -> 0.22979169
B29: Total | C29: =SUM(C26:C28) -> 295 | D29: =SUM(D26:D28) -> 7633 | E29: =IF(C29=0,0,D29/C29) -> 25.874576 | F29: =SUM(F26:F28) -> 1
B31: Pergunta 2: renovação automática (respeita plano e tipo; mostra Yes e No)
B32: Renovação automática | C32: Assinaturas | D32: Faturamento | E32: Ticket médio | F32: Cupom médio
B33: Yes | C33: =COUNTIFS(Bases!$C$2:$C$1000,$C$4,Bases!$G$2:$G$1000,$C$5,Bases!$E$2:$E$1000,$B33) -> 148 | D33: =SUMIFS(Bases!$M$2:$M$1000,Bases!$C$2:$C$1000,$C$4,Bases!$G$2:$G$1000,$C$5,Bases!$E$2:$E$1000,$B33) -> 3786 | E33: =IF(C33=0,0,D33/C33) -> 25.581081 | F33: =IF(C33=0,0,SUMIFS(Bases!$L$2:$L$1000,Bases!$C$2:$C$1000,$C$4,Bases!$G$2:$G$1000,$C$5,Bases!$E$2:$E$1000,$B33)/C33) -> 7.1554054
B34: No | C34: =COUNTIFS(Bases!$C$2:$C$1000,$C$4,Bases!$G$2:$G$1000,$C$5,Bases!$E$2:$E$1000,$B34) -> 147 | D34: =SUMIFS(Bases!$M$2:$M$1000,Bases!$C$2:$C$1000,$C$4,Bases!$G$2:$G$1000,$C$5,Bases!$E$2:$E$1000,$B34) -> 3847 | E34: =IF(C34=0,0,D34/C34) -> 26.170068 | F34: =IF(C34=0,0,SUMIFS(Bases!$L$2:$L$1000,Bases!$C$2:$C$1000,$C$4,Bases!$G$2:$G$1000,$C$5,Bases!$E$2:$E$1000,$B34)/C34) -> 7.2312925
B35: Total | C35: =SUM(C33:C34) -> 295 | D35: =SUM(D33:D34) -> 7633 | E35: =IF(C35=0,0,D35/C35) -> 25.874576 | F35: =IF(C35=0,0,(F33*C33+F34*C34)/C35) -> 7.1932203
B37: Pergunta 3: composição do valor por plano (respeita tipo e renovação; mostra todos os planos)
B38: Plano | C38: Assinatura base | D38: EA Play | E38: Minecraft | F38: Cupons | G38: Faturamento
B39: Core | C39: =SUMIFS(Bases!$F$2:$F$1000,Bases!$C$2:$C$1000,$B39,Bases!$G$2:$G$1000,$C$5,Bases!$E$2:$E$1000,$C$6) -> 505 | D39: =SUMIFS(Bases!$O$2:$O$1000,Bases!$C$2:$C$1000,$B39,Bases!$G$2:$G$1000,$C$5,Bases!$E$2:$E$1000,$C$6) -> 0 | E39: =SUMIFS(Bases!$K$2:$K$1000,Bases!$C$2:$C$1000,$B39,Bases!$G$2:$G$1000,$C$5,Bases!$E$2:$E$1000,$C$6) -> 0 | F39: =SUMIFS(Bases!$L$2:$L$1000,Bases!$C$2:$C$1000,$B39,Bases!$G$2:$G$1000,$C$5,Bases!$E$2:$E$1000,$C$6) -> 61 | G39: =SUMIFS(Bases!$M$2:$M$1000,Bases!$C$2:$C$1000,$B39,Bases!$G$2:$G$1000,$C$5,Bases!$E$2:$E$1000,$C$6) -> 444
B40: Standard | C40: =SUMIFS(Bases!$F$2:$F$1000,Bases!$C$2:$C$1000,$B40,Bases!$G$2:$G$1000,$C$5,Bases!$E$2:$E$1000,$C$6) -> 960 | D40: =SUMIFS(Bases!$O$2:$O$1000,Bases!$C$2:$C$1000,$B40,Bases!$G$2:$G$1000,$C$5,Bases!$E$2:$E$1000,$C$6) -> 0 | E40: =SUMIFS(Bases!$K$2:$K$1000,Bases!$C$2:$C$1000,$B40,Bases!$G$2:$G$1000,$C$5,Bases!$E$2:$E$1000,$C$6) -> 1920 | F40: =SUMIFS(Bases!$L$2:$L$1000,Bases!$C$2:$C$1000,$B40,Bases!$G$2:$G$1000,$C$5,Bases!$E$2:$E$1000,$C$6) -> 1079 | G40: =SUMIFS(Bases!$M$2:$M$1000,Bases!$C$2:$C$1000,$B40,Bases!$G$2:$G$1000,$C$5,Bases!$E$2:$E$1000,$C$6) -> 1801
B41: Ultimate | C41: =SUMIFS(Bases!$F$2:$F$1000,Bases!$C$2:$C$1000,$B41,Bases!$G$2:$G$1000,$C$5,Bases!$E$2:$E$1000,$C$6) -> 1470 | D41: =SUMIFS(Bases!$O$2:$O$1000,Bases!$C$2:$C$1000,$B41,Bases!$G$2:$G$1000,$C$5,Bases!$E$2:$E$1000,$C$6) -> 2940 | E41: =SUMIFS(Bases!$K$2:$K$1000,Bases!$C$2:$C$1000,$B41,Bases!$G$2:$G$1000,$C$5,Bases!$E$2:$E$1000,$C$6) -> 1960 | F41: =SUMIFS(Bases!$L$2:$L$1000,Bases!$C$2:$C$1000,$B41,Bases!$G$2:$G$1000,$C$5,Bases!$E$2:$E$1000,$C$6) -> 982 | G41: =SUMIFS(Bases!$M$2:$M$1000,Bases!$C$2:$C$1000,$B41,Bases!$G$2:$G$1000,$C$5,Bases!$E$2:$E$1000,$C$6) -> 5388
B42: Total | C42: =SUM(C39:C41) -> 2935 | D42: =SUM(D39:D41) -> 2940 | E42: =SUM(E39:E41) -> 3880 | F42: =SUM(F39:F41) -> 2122 | G42: =SUM(G39:G41) -> 7633
B44: Pergunta 4: evolução mensal (respeita os três filtros)
B45: Mês | C45: Início do mês | D45: Assinaturas | E45: Faturamento
B46: Jan | C46: =DATE(YEAR(MIN(Bases!$D$2:$D$1000)),1,1) -> 45292 | D46: =COUNTIFS(Bases!$C$2:$C$1000,$C$4,Bases!$G$2:$G$1000,$C$5,Bases!$E$2:$E$1000,$C$6,Bases!$N$2:$N$1000,$C46) -> 2 | E46: =SUMIFS(Bases!$M$2:$M$1000,Bases!$C$2:$C$1000,$C$4,Bases!$G$2:$G$1000,$C$5,Bases!$E$2:$E$1000,$C$6,Bases!$N$2:$N$1000,$C46) -> 65
B47: Fev | C47: =DATE(YEAR(MIN(Bases!$D$2:$D$1000)),2,1) -> 45323 | D47: =COUNTIFS(Bases!$C$2:$C$1000,$C$4,Bases!$G$2:$G$1000,$C$5,Bases!$E$2:$E$1000,$C$6,Bases!$N$2:$N$1000,$C47) -> 2 | E47: =SUMIFS(Bases!$M$2:$M$1000,Bases!$C$2:$C$1000,$C$4,Bases!$G$2:$G$1000,$C$5,Bases!$E$2:$E$1000,$C$6,Bases!$N$2:$N$1000,$C47) -> 82
...

Sheet Bases
A1: Subscriber ID | B1: Name | C1: Plan | D1: Start Date | E1: Auto Renewal | F1: Subscription Price | G1: Subscription Type | H1: EA Play Season Pass | I1: EA Play Season Pass Price | J1: Minecraft Season Pass | K1: Minecraft Season Pass Price | L1: Coupon Value | M1: Total Value | N1: Mês (auxiliar) | O1: EA Play valor (auxiliar) | P1: Valor bruto (auxiliar) | Q1: Conferência (auxiliar)
A2: 3231 | B2: João Silva | C2: Ultimate | D2: 45292 | E2: Yes | F2: 15 | G2: Monthly | H2: Yes | I2: 30 | J2: Yes | K2: 20 | L2: 5 | M2: 60 | N2: =IF(D2="","",DATE(YEAR(D2),MONTH(D2),1)) -> 45292 | O2: =IF(A2="","",IF(ISNUMBER(I2),I2,0)) -> 30 | P2: =IF(A2="","",F2+O2+K2) -> 65 | Q2: =IF(A2="","",IF(P2-L2=M2,"OK","Divergente")) -> OK
A3: 3232 | B3: Maria Oliveira | C3: Core | D3: 45306 | E3: No | F3: 5 | G3: Annual | H3: No | I3: - | J3: No | K3: 0 | L3: 0 | M3: 5 | N3: =IF(D3="","",DATE(YEAR(D3),MONTH(D3),1)) -> 45292 | O3: =IF(A3="","",IF(ISNUMBER(I3),I3,0)) -> 0 | P3: =IF(A3="","",F3+O3+K3) -> 5 | Q3: =IF(A3="","",IF(P3-L3=M3,"OK","Divergente")) -> OK
A4: 3233 | B4: Lucas Fernandes | C4: Standard | D4: 45332 | E4: Yes | F4: 10 | G4: Quarterly | H4: No | I4: - | J4: Yes | K4: 20 | L4: 10 | M4: 20 | N4: =IF(D4="","",DATE(YEAR(D4),MONTH(D4),1)) -> 45323 | O4: =IF(A4="","",IF(ISNUMBER(I4),I4,0)) -> 0 | P4: =IF(A4="","",F4+O4+K4) -> 30 | Q4: =IF(A4="","",IF(P4-L4=M4,"OK","Divergente")) -> OK
A5: 3234 | B5: Ana Souza | C5: Ultimate | D5: 45342 | E5: No | F5: 15 | G5: Monthly | H5: Yes | I5: 30 | J5: Yes | K5: 20 | L5: 3 | M5: 62 | N5: =IF(D5="","",DATE(YEAR(D5),MONTH(D5),1)) -> 45323 | O5: =IF(A5="","",IF(ISNUMBER(I5),I5,0)) -> 30 | P5: =IF(A5="","",F5+O5+K5) -> 65 | Q5: =IF(A5="","",IF(P5-L5=M5,"OK","Divergente")) -> OK
A6: 3235 | B6: Pedro Gonçalves | C6: Core | D6: 45356 | E6: Yes | F6: 5 | G6: Monthly | H6: No | I6: - | J6: No | K6: 0 | L6: 1 | M6: 4 | N6: =IF(D6="","",DATE(YEAR(D6),MONTH(D6),1)) -> 45352 | O6: =IF(A6="","",IF(ISNUMBER(I6),I6,0)) -> 0 | P6: =IF(A6="","",F6+O6+K6) -> 5 | Q6: =IF(A6="","",IF(P6-L6=M6,"OK","Divergente")) -> OK
A7: 3236 | B7: Felipe Costa | C7: Standard | D7: 45353 | E7: No | F7: 10 | G7: Monthly | H7: No | I7: - | J7: Yes | K7: 20 | L7: 2 | M7: 28 | N7: =IF(D7="","",DATE(YEAR(D7),MONTH(D7),1)) -> 45352 | O7: =IF(A7="","",IF(ISNUMBER(I7),I7,0)) -> 0 | P7: =IF(A7="","",F7+O7+K7) -> 30 | Q7: =IF(A7="","",IF(P7-L7=M7,"OK","Divergente")) -> OK
A8: 3237 | B8: Camila Ribeiro | C8: Ultimate | D8: 45354 | E8: Yes | F8: 15 | G8: Quarterly | H8: Yes | I8: 30 | J8: Yes | K8: 20 | L8: 10 | M8: 55 | N8: =IF(D8="","",DATE(YEAR(D8),MONTH(D8),1)) -> 45352 | O8: =IF(A8="","",IF(ISNUMBER(I8),I8,0)) -> 30 | P8: =IF(A8="","",F8+O8+K8) -> 65 | Q8: =IF(A8="","",IF(P8-L8=M8,"OK","Divergente")) -> OK
A9: 3238 | B9: André Mendes | C9: Core | D9: 45355 | E9: Yes | F9: 5 | G9: Annual | H9: No | I9: - | J9: No | K9: 0 | L9: 0 | M9: 5 | N9: =IF(D9="","",DATE(YEAR(D9),MONTH(D9),1)) -> 45352 | O9: =IF(A9="","",IF(ISNUMBER(I9),I9,0)) -> 0 | P9: =IF(A9="","",F9+O9+K9) -> 5 | Q9: =IF(A9="","",IF(P9-L9=M9,"OK","Divergente")) -> OK
A10: 3239 | B10: Sofia Almeida | C10: Ultimate | D10: 45356 | E10: No | F10: 15 | G10: Monthly | H10: Yes | I10: 30 | J10: Yes | K10: 20 | L10: 5 | M10: 60 | N10: =IF(D10="","",DATE(YEAR(D10),MONTH(D10),1)) -> 45352 | O10: =IF(A10="","",IF(ISNUMBER(I10),I10,0)) -> 30 | P10: =IF(A10="","",F10+O10+K10) -> 65 | Q10: =IF(A10="","",IF(P10-L10=M10,"OK","Divergente")) -> OK
A11: 3240 | B11: Bruno Martins | C11: Standard | D11: 45357 | E11: Yes | F11: 10 | G11: Quarterly | H11: No | I11: - | J11: Yes | K11: 20 | L11: 15 | M11: 15 | N11: =IF(D11="","",DATE(YEAR(D11),MONTH(D11),1)) -> 45352 | O11: =IF(A11="","",IF(ISNUMBER(I11),I11,0)) -> 0 | P11: =IF(A11="","",F11+O11+K11) -> 30 | Q11: =IF(A11="","",IF(P11-L11=M11,"OK","Divergente")) -> OK
A12: 3241 | B12: Rita Castro | C12: Core | D12: 45358 | E12: No | F12: 5 | G12: Monthly | H12: No | I12: - | J12: No | K12: 0 | L12: 1 | M12: 4 | N12: =IF(D12="","",DATE(YEAR(D12),MONTH(D12),1)) -> 45352 | O12: =IF(A12="","",IF(ISNUMBER(I12),I12,0)) -> 0 | P12: =IF(A12="","",F12+O12+K12) -> 5 | Q12: =IF(A12="","",IF(P12-L12=M12,"OK","Divergente")) -> OK
A13: 3242 | B13: Marco Túlio | C13: Ultimate | D13: 45359 | E13: Yes | F13: 15 | G13: Annual | H13: Yes | I13: 30 | J13: Yes | K13: 20 | L13: 20 | M13: 45 | N13: =IF(D13="","",DATE(YEAR(D13),MONTH(D13),1)) -> 45352 | O13: =IF(A13="","",IF(ISNUMBER(I13),I13,0)) -> 30 | P13: =IF(A13="","",F13+O13+K13) -> 65 | Q13: =IF(A13="","",IF(P13-L13=M13,"OK","Divergente")) -> OK
A14: 3243 | B14: Lívia Silveira | C14: Standard | D14: 45360 | E14: No | F14: 10 | G14: Monthly | H14: No | I14: - | J14: Yes | K14: 20 | L14: 10 | M14: 20 | N14: =IF(D14="","",DATE(YEAR(D14),MONTH(D14),1)) -> 45352 | O14: =IF(A14="","",IF(ISNUMBER(I14),I14,0)) -> 0 | P14: =IF(A14="","",F14+O14+K14) -> 30 | Q14: =IF(A14="","",IF(P14-L14=M14,"OK","Divergente")) -> OK
A15: 3244 | B15: Diogo Sousa | C15: Core | D15: 45361 | E15: Yes | F15: 5 | G15: Quarterly | H15: No | I15: - | J15: No | K15: 0 | L15: 0 | M15: 5 | N15: =IF(D15="","",DATE(YEAR(D15),MONTH(D15),1)) -> 45352 | O15: =IF(A15="","",IF(ISNUMBER(I15),I15,0)) -> 0 | P15: =IF(A15="","",F15+O15+K15) -> 5 | Q15: =IF(A15="","",IF(P15-L15=M15,"OK","Divergente")) -> OK
A16: 3245 | B16: Fernanda Lima | C16: Ultimate | D16: 45362 | E16: No | F16: 15 | G16: Monthly | H16: Yes | I16: 30 | J16: Yes | K16: 20 | L16: 8 | M16: 57 | N16: =IF(D16="","",DATE(YEAR(D16),MONTH(D16),1)) -> 45352 | O16: =IF(A16="","",IF(ISNUMBER(I16),I16,0)) -> 30 | P16: =IF(A16="","",F16+O16+K16) -> 65 | Q16: =IF(A16="","",IF(P16-L16=M16,"OK","Divergente")) -> OK
A17: 3246 | B17: Caio Pereira | C17: Standard | D17: 45363 | E17: Yes | F17: 10 | G17: Annual | H17: No | I17: - | J17: Yes | K17: 20 | L17: 12 | M17: 18 | N17: =IF(D17="","",DATE(YEAR(D17),MONTH(D17),1)) -> 45352 | O17: =IF(A17="","",IF(ISNUMBER(I17),I17,0)) -> 0 | P17: =IF(A17="","",F17+O17+K17) -> 30 | Q17: =IF(A17="","",IF(P17-L17=M17,"OK","Divergente")) -> OK
A18: 3247 | B18: Beatriz Gomes | C18: Core | D18: 45364 | E18: No | F18: 5 | G18: Monthly | H18: No | I18: - | J18: No | K18: 0 | L18: 2 | M18: 3 | N18: =IF(D18="","",DATE(YEAR(D18),MONTH(D18),1)) -> 45352 | O18: =IF(A18="","",IF(ISNUMBER(I18),I18,0)) -> 0 | P18: =IF(A18="","",F18+O18+K18) -> 5 | Q18: =IF(A18="","",IF(P18-L18=M18,"OK","Divergente")) -> OK
A19: 3248 | B19: Cesar Oliveira | C19: Ultimate | D19: 45365 | E19: Yes | F19: 15 | G19: Quarterly | H19: Yes | I19: 30 | J19: Yes | K19: 20 | L19: 7 | M19: 58 | N19: =IF(D19="","",DATE(YEAR(D19),MONTH(D19),1)) -> 45352 | O19: =IF(A19="","",IF(ISNUMBER(I19),I19,0)) -> 30 | P19: =IF(A19="","",F19+O19+K19) -> 65 | Q19: =IF(A19="","",IF(P19-L19=M19,"OK","Divergente")) -> OK
A20: 3249 | B20: Débora Machado | C20: Standard | D20: 45366 | E20: No | F20: 10 | G20: Monthly | H20: No | I20: - | J20: Yes | K20: 20 | L20: 5 | M20: 25 | N20: =IF(D20="","",DATE(YEAR(D20),MONTH(D20),1)) -> 45352 | O20: =IF(A20="","",IF(ISNUMBER(I20),I20,0)) -> 0 | P20: =IF(A20="","",F20+O20+K20) -> 30 | Q20: =IF(A20="","",IF(P20-L20=M20,"OK","Divergente")) -> OK
A21: 3250 | B21: Eduardo Vargas | C21: Core | D21: 45367 | E21: Yes | F21: 5 | G21: Annual | H21: No | I21: - | J21: No | K21: 0 | L21: 0 | M21: 5 | N21: =IF(D21="","",DATE(YEAR(D21),MONTH(D21),1)) -> 45352 | O21: =IF(A21="","",IF(ISNUMBER(I21),I21,0)) -> 0 | P21: =IF(A21="","",F21+O21+K21) -> 5 | Q21: =IF(A21="","",IF(P21-L21=M21,"OK","Divergente")) -> OK
A22: 3251 | B22: Gabriela Santos | C22: Ultimate | D22: 45368 | E22: No | F22: 15 | G22: Monthly | H22: Yes | I22: 30 | J22: Yes | K22: 20 | L22: 3 | M22: 62 | N22: =IF(D22="","",DATE(YEAR(D22),MONTH(D22),1)) -> 45352 | O22: =IF(A22="","",IF(ISNUMBER(I22),I22,0)) -> 30 | P22: =IF(A22="","",F22+O22+K22) -> 65 | Q22: =IF(A22="","",IF(P22-L22=M22,"OK","Divergente")) -> OK
A23: 3252 | B23: Henrique Dias | C23: Standard | D23: 45369 | E23: Yes | F23: 10 | G23: Quarterly | H23: No | I23: - | J23: Yes | K23: 20 | L23: 15 | M23: 15 | N23: =IF(D23="","",DATE(YEAR(D23),MONTH(D23),1)) -> 45352 | O23: =IF(A23="","",IF(ISNUMBER(I23),I23,0)) -> 0 | P23: =IF(A23="","",F23+O23+K23) -> 30 | Q23: =IF(A23="","",IF(P23-L23=M23,"OK","Divergente")) -> OK
A24: 3253 | B24: Isabela Moreira | C24: Core | D24: 45370 | E24: No | F24: 5 | G24: Monthly | H24: No | I24: - | J24: No | K24: 0 | L24: 1 | M24: 4 | N24: =IF(D24="","",DATE(YEAR(D24),MONTH(D24),1)) -> 45352 | O24: =IF(A24="","",IF(ISNUMBER(I24),I24,0)) -> 0 | P24: =IF(A24="","",F24+O24+K24) -> 5 | Q24: =IF(A24="","",IF(P24-L24=M24,"OK","Divergente")) -> OK
A25: 3254 | B25: Joaquim Barbosa | C25: Ultimate | D25: 45371 | E25: Yes | F25: 15 | G25: Annual | H25: Yes | I25: 30 | J25: Yes | K25: 20 | L25: 20 | M25: 45 | N25: =IF(D25="","",DATE(YEAR(D25),MONTH(D25),1)) -> 45352 | O25: =IF(A25="","",IF(ISNUMBER(I25),I25,0)) -> 30 | P25: =IF(A25="","",F25+O25+K25) -> 65 | Q25: =IF(A25="","",IF(P25-L25=M25,"OK","Divergente")) -> OK
A26: 3255 | B26: Lara Rocha | C26: Standard | D26: 45372 | E26: No | F26: 10 | G26: Monthly | H26: No | I26: - | J26: Yes | K26: 20 | L26: 10 | M26: 20 | N26: =IF(D26="","",DATE(YEAR(D26),MONTH(D26),1)) -> 45352 | O26: =IF(A26="","",IF(ISNUMBER(I26),I26,0)) -> 0 | P26: =IF(A26="","",F26+O26+K26) -> 30 | Q26: =IF(A26="","",IF(P26-L26=M26,"OK","Divergente")) -> OK
A27: 3256 | B27: Matheus Silva | C27: Core | D27: 45373 | E27: Yes | F27: 5 | G27: Quarterly | H27: No | I27: - | J27: No | K27: 0 | L27: 0 | M27: 5 | N27: =IF(D27="","",DATE(YEAR(D27),MONTH(D27),1)) -> 45352 | O27: =IF(A27="","",IF(ISNUMBER(I27),I27,0)) -> 0 | P27: =IF(A27="","",F27+O27+K27) -> 5 | Q27: =IF(A27="","",IF(P27-L27=M27,"OK","Divergente")) -> OK
A28: 3257 | B28: Nicole Costa | C28: Ultimate | D28: 45374 | E28: No | F28: 15 | G28: Monthly | H28: Yes | I28: 30 | J28: Yes | K28: 20 | L28: 5 | M28: 60 | N28: =IF(D28="","",DATE(YEAR(D28),MONTH(D28),1)) -> 45352 | O28: =IF(A28="","",IF(ISNUMBER(I28),I28,0)) -> 30 | P28: =IF(A28="","",F28+O28+K28) -> 65 | Q28: =IF(A28="","",IF(P28-L28=M28,"OK","Divergente")) -> OK
A29: 3258 | B29: Otávio Mendonça | C29: Standard | D29: 45375 | E29: Yes | F29: 10 | G29: Annual | H29: No | I29: - | J29: Yes | K29: 20 | L29: 15 | M29: 15 | N29: =IF(D29="","",DATE(YEAR(D29),MONTH(D29),1)) -> 45352 | O29: =IF(A29="","",IF(ISNUMBER(I29),I29,0)) -> 0 | P29: =IF(A29="","",F29+O29+K29) -> 30 | Q29: =IF(A29="","",IF(P29-L29=M29,"OK","Divergente")) -> OK
A30: 3259 | B30: Paula Ferreira | C30: Core | D30: 45376 | E30: No | F30: 5 | G30: Monthly | H30: No | I30: - | J30: No | K30: 0 | L30: 1 | M30: 4 | N30: =IF(D30="","",DATE(YEAR(D30),MONTH(D30),1)) -> 45352 | O30: =IF(A30="","",IF(ISNUMBER(I30),I30,0)) -> 0 | P30: =IF(A30="","",F30+O30+K30) -> 5 | Q30: =IF(A30="","",IF(P30-L30=M30,"OK","Divergente")) -> OK
A31: 3260 | B31: Raquel Alves | C31: Ultimate | D31: 45377 | E31: Yes | F31: 15 | G31: Quarterly | H31: Yes | I31: 30 | J31: Yes | K31: 20 | L31: 7 | M31: 58 | N31: =IF(D31="","",DATE(YEAR(D31),MONTH(D31),1)) -> 45352 | O31: =IF(A31="","",IF(ISNUMBER(I31),I31,0)) -> 30 | P31: =IF(A31="","",F31+O31+K31) -> 65 | Q31: =IF(A31="","",IF(P31-L31=M31,"OK","Divergente")) -> OK
A32: 3261 | B32: Samuel Pires | C32: Standard | D32: 45378 | E32: No | F32: 10 | G32: Monthly | H32: No | I32: - | J32: Yes | K32: 20 | L32: 10 | M32: 20 | N32: =IF(D32="","",DATE(YEAR(D32),MONTH(D32),1)) -> 45352 | O32: =IF(A32="","",IF(ISNUMBER(I32),I32,0)) -> 0 | P32: =IF(A32="","",F32+O32+K32) -> 30 | Q32: =IF(A32="","",IF(P32-L32=M32,"OK","Divergente")) -> OK
A33: 3262 | B33: Tânia Barros | C33: Core | D33: 45379 | E33: Yes | F33: 5 | G33: Annual | H33: No | I33: - | J33: No | K33: 0 | L33: 0 | M33: 5 | N33: =IF(D33="","",DATE(YEAR(D33),MONTH(D33),1)) -> 45352 | O33: =IF(A33="","",IF(ISNUMBER(I33),I33,0)) -> 0 | P33: =IF(A33="","",F33+O33+K33) -> 5 | Q33: =IF(A33="","",IF(P33-L33=M33,"OK","Divergente")) -> OK
A34: 3263 | B34: Vinicius Lima | C34: Ultimate | D34: 45380 | E34: No | F34: 15 | G34: Monthly | H34: Yes | I34: 30 | J34: Yes | K34: 20 | L34: 3 | M34: 62 | N34: =IF(D34="","",DATE(YEAR(D34),MONTH(D34),1)) -> 45352 | O34: =IF(A34="","",IF(ISNUMBER(I34),I34,0)) -> 30 | P34: =IF(A34="","",F34+O34+K34) -> 65 | Q34: =IF(A34="","",IF(P34-L34=M34,"OK","Divergente")) -> OK
A35: 3264 | B35: Yasmin Teixeira | C35: Standard | D35: 45381 | E35: Yes | F35: 10 | G35: Quarterly | H35: No | I35: - | J35: Yes | K35: 20 | L35: 15 | M35: 15 | N35: =IF(D35="","",DATE(YEAR(D35),MONTH(D35),1)) -> 45352 | O35: =IF(A35="","",IF(ISNUMBER(I35),I35,0)) -> 0 | P35: =IF(A35="","",F35+O35+K35) -> 30 | Q35: =IF(A35="","",IF(P35-L35=M35,"OK","Divergente")) -> OK
A36: 3265 | B36: Zé Carlos | C36: Core | D36: 45382 | E36: No | F36: 5 | G36: Monthly | H36: No | I36: - | J36: No | K36: 0 | L36: 1 | M36: 4 | N36: =IF(D36="","",DATE(YEAR(D36),MONTH(D36),1)) -> 45352 | O36: =IF(A36="","",IF(ISNUMBER(I36),I36,0)) -> 0 | P36: =IF(A36="","",F36+O36+K36) -> 5 | Q36: =IF(A36="","",IF(P36-L36=M36,"OK","Divergente")) -> OK
A37: 3266 | B37: Amanda Nogueira | C37: Core | D37: 45383 | E37: Yes | F37: 5 | G37: Monthly | H37: No | I37: - | J37: No | K37: 0 | L37: 0 | M37: 5 | N37: =IF(D37="","",DATE(YEAR(D37),MONTH(D37),1)) -> 45383 | O37: =IF(A37="","",IF(ISNUMBER(I37),I37,0)) -> 0 | P37: =IF(A37="","",F37+O37+K37) -> 5 | Q37: =IF(A37="","",IF(P37-L37=M37,"OK","Divergente")) -> OK
A38: 3267 | B38: Bruno Cavalheiro | C38: Ultimate | D38: 45384 | E38: No | F38: 15 | G38: Quarterly | H38: Yes | I38: 30 | J38: Yes | K38: 20 | L38: 7 | M38: 58 | N38: =IF(D38="","",DATE(YEAR(D38),MONTH(D38),1)) -> 45383 | O38: =IF(A38="","",IF(ISNUMBER(I38),I38,0)) -> 30 | P38: =IF(A38="","",F38+O38+K38) -> 65 | Q38: =IF(A38="","",IF(P38-L38=M38,"OK","Divergente")) -> OK
A39: 3268 | B39: Carla Dias | C39: Standard | D39: 45385 | E39: Yes | F39: 10 | G39: Annual | H39: No | I39: - | J39: Yes | K39: 20 | L39: 10 | M39: 20 | N39: =IF(D39="","",DATE(YEAR(D39),MONTH(D39),1)) -> 45383 | O39: =IF(A39="","",IF(ISNUMBER(I39),I39,0)) -> 0 | P39: =IF(A39="","",F39+O39+K39) -> 30 | Q39: =IF(A39="","",IF(P39-L39=M39,"OK","Divergente")) -> OK
A40: 3269 | B40: Diego Fontes | C40: Core | D40: 45386 | E40: No | F40: 5 | G40: Quarterly | H40: No | I40: - | J40: No | K40: 0 | L40: 1 | M40: 4 | N40: =IF(D40="","",DATE(YEAR(D40),MONTH(D40),1)) -> 45383 | O40: =IF(A40="","",IF(ISNUMBER(I40),I40,0)) -> 0 | P40: =IF(A40="","",F40+O40+K40) -> 5 | Q40: =IF(A40="","",IF(P40-L40=M40,"OK","Divergente")) -> OK
...
